<?xml version="1.0"?>
<robot name="jaguar">
  <link name="base_link">
    <visual>
      <geometry>
        <mesh filename="/home/peter/rosw/robot_model/urdf/gaz_models/cleaned_c/Jaguar-IND-arms-body-only_clean.stl" scale="0.001 .001 .001"/>
      </geometry>
	<origin rpy="0 0 0" xyz="0 0 0"/>
      <material name="marine">
        <color rgba="0.3 0.1 .1 2"/>
      </material>
    </visual>
    <collision>
      <origin rpy="0 0 0" xyz="0 0 0"/>  
      <geometry>
	<!--use simplified model for collisions -->
         <mesh filename="/home/peter/rosw/robot_model/urdf/gaz_models/cleaned_c/Jaguar-IND-arms-body-only_hull.stl" scale="0.001 .001 .001"/>
      </geometry>
    </collision>
    <inertial>
      <mass value="40"/>
      <inertia ixx="1.0" ixy="0.0" ixz="0.0" iyy="1.0" iyz="0.0" izz="1.0"/>
    </inertial>
  </link>

  <link name="right_link">
    <visual>
      <geometry>
        <mesh filename="/home/peter/rosw/robot_model/urdf/gaz_models/cleaned_c/Jaguar-IND-arms-only 1.stl" scale="0.001 .001 .001"/>
      </geometry>
      <origin rpy="0 0 0" xyz="0 0 0"/>
      <material name="brown">
        <color rgba="0.5 0.2 0.2 5"/>
      </material>
    </visual>
    <collision>
      <origin rpy="0 0 0" xyz="0 0 0"/>
      <geometry>
         <!--use simplified model for collisions -->
         <mesh filename="/home/peter/rosw/robot_model/urdf/gaz_models/cleaned_c/Jaguar-IND-arms-only 1 hull.stl" scale="0.001 .001 .001"/>
     </geometry>
    </collision>
    <inertial>
      <mass value="3"/>
      <inertia ixx="1.0" ixy="0.0" ixz="0.0" iyy="1.0" iyz="0.0" izz="1.0"/>
    </inertial>
  </link>

  <joint name="base_to_right_link" type="continuous">
    <axis xyz="0 1 0"/>
    <parent link="base_link"/>
    <child link="right_link"/>
    <origin xyz="-0.235 0.33 0"/>
    <limit effort="100" velocity="100"/>
    <dynamics damping="1" friction="0.2"/>
  </joint>

  <link name="left_link">
    <visual>
      <geometry>
        <mesh filename="/home/peter/rosw/robot_model/urdf/gaz_models/cleaned_c/Jaguar-IND-arms-only 2.stl" scale="0.001 .001 .001"/>
      </geometry>
      <origin rpy="0 0 0" xyz="0 0 0"/>
      <material name="brown"/>
    </visual>
    <collision>
      <origin rpy="0 0 0" xyz="0 0 0"/>
      <geometry>
	 <!--use simplified model for collisions -->
         <mesh filename="/home/peter/rosw/robot_model/urdf/gaz_models/cleaned_c/Jaguar-IND-arms-only 2 hull.stl" scale="0.001 .001 .001"/>
      </geometry>
    </collision>
    <inertial>
      <mass value="3"/>
      <inertia ixx="1.0" ixy="0.0" ixz="0.0" iyy="1.0" iyz="0.0" izz="1.0"/>
    </inertial>
  </link>

  <joint name="base_to_left_link" type="continuous">
    <axis xyz="0 1 0"/>
    <parent link="base_link"/>
    <child link="left_link"/>
    <origin xyz="-0.235 -0.33 0"/>
    <limit effort="100" velocity="100"/>
    <dynamics damping="1" friction="0.2"/>
  </joint>

<!-- Mounting plate-->
  <link name="mounting_plate">
    <visual>
      <geometry>
        <mesh filename="/home/peter/rosw/robot_model/urdf/gaz_models/cleaned_c/jaguar_mountig_plate_full.stl" scale="0.001 .001 .001"/>
      </geometry>
      <origin rpy="0 0 0" xyz="0 0 0"/>
      <material name="brown"/>
    </visual>
    <collision>
      <origin rpy="0 0 0" xyz="0 0 0"/>
      <geometry>
	 <!--use simplified model for collisions -->
         <mesh filename="/home/peter/rosw/robot_model/urdf/gaz_models/cleaned_c/jaguar_mountig_plate_full.stl" scale="0.001 .001 .001"/>
      </geometry>
    </collision>
    <inertial>
      <mass value="3"/>
      <inertia ixx="1.0" ixy="0.0" ixz="0.0" iyy="1.0" iyz="0.0" izz="1.0"/>
    </inertial>
  </link>

  <joint name="base_to_mounting_plate" type="fixed">
    <axis xyz="0 1 0"/>
    <parent link="base_link"/>
    <child link="mounting_plate"/>
    <origin xyz="-0.025 0 0.355"/>
  </joint>

<!-- LA Servo 1-->
  <link name="LA_Servo1">
    <visual>
      <geometry>
        <mesh filename="/home/peter/rosw/robot_model/urdf/gaz_models/cleaned_c/laser_alignment_assembly_servo1.stl" scale="0.001 .001 .001"/>
      </geometry>
      <origin rpy="0 0 0" xyz="0 0 0"/>
      <material name="brown"/>
    </visual>
    <collision>
      <origin rpy="0 0 0" xyz="0 0 0"/>
      <geometry>
	 <!--use simplified model for collisions -->
         <mesh filename="/home/peter/rosw/robot_model/urdf/gaz_models/cleaned_c/laser_alignment_assembly_servo1.stl" scale="0.001 .001 .001"/>
      </geometry>
    </collision>
    <inertial>
      <mass value="3"/>
      <inertia ixx="1.0" ixy="0.0" ixz="0.0" iyy="1.0" iyz="0.0" izz="1.0"/>
    </inertial>
  </link>

  <joint name="mount_plate_to_LA_Servo1_link" type="continuous">
    <axis xyz="0 1 0"/>
    <parent link="mounting_plate"/>
    <child link="LA_Servo1"/>
    <origin xyz="-0.215 -0.002 -0.134"/>
    <limit effort="100" velocity="100"/>
    <dynamics damping="1" friction="0.2"/>
  </joint>

<!-- LA Servo 2-->
 <link name="LA_Servo2">
    <visual>
      <geometry>
        <mesh filename="/home/peter/rosw/robot_model/urdf/gaz_models/cleaned_c/laser_alignment_assembly_scanner.stl" scale="0.001 .001 .001"/>
      </geometry>
      <origin rpy="0 0 0" xyz="0 0 0"/>
      <material name="brown"/>
    </visual>
    <collision>
      <origin rpy="0 0 0" xyz="0 0 0"/>
      <geometry>
         <mesh filename="/home/peter/rosw/robot_model/urdf/gaz_models/cleaned_c/laser_alignment_assembly_scanner.stl" scale="0.001 .001 .001"/>
      </geometry>
    </collision>
    <inertial>
      <mass value="3"/>
      <inertia ixx="1.0" ixy="0.0" ixz="0.0" iyy="1.0" iyz="0.0" izz="1.0"/>
    </inertial>
  </link>

  <joint name="mount_plate_to_LA_Servo2_link" type="continuous">
    <axis xyz="0 1 0"/>
    <parent link="mounting_plate"/>
    <child link="LA_Servo2"/>
    <origin xyz="-0.215 -0.002 -0.065"/>
    <limit effort="100" velocity="100"/>
    <dynamics damping="1" friction="0.2"/>
  </joint>

<!-- SH Servo 1-->
  <link name="SH_Servo1">
    <visual>
      <geometry>
        <mesh filename="/home/peter/rosw/robot_model/urdf/gaz_models/cleaned_c/sensor_head_servo1.stl" scale="0.001 .001 .001"/>
      </geometry>
      <origin rpy="0 0 0" xyz="0 0 0"/>
      <material name="brown"/>
    </visual>
    <collision>
      <origin rpy="0 0 0" xyz="0 0 0"/>
      <geometry>
	 <!--use simplified model for collisions -->
         <mesh filename="/home/peter/rosw/robot_model/urdf/gaz_models/cleaned_c/sensor_head_servo1.stl" scale="0.001 .001 .001"/>
      </geometry>
    </collision>
    <inertial>
      <mass value="3"/>
      <inertia ixx="1.0" ixy="0.0" ixz="0.0" iyy="1.0" iyz="0.0" izz="1.0"/>
    </inertial>
  </link>

  <joint name="mount_plate_to_SH_Servo1_link" type="continuous">
    <axis xyz="0 1 0"/>
    <parent link="mounting_plate"/>
    <child link="SH_Servo1"/>
    <origin xyz="-0.054 -0.002 0.066"/>
    <limit effort="100" velocity="100"/>
    <dynamics damping="1" friction="0.2"/>
  </joint>

<!-- SH Servo 2-->
  <link name="SH_Servo2">
    <visual>
      <geometry>
        <mesh filename="/home/peter/rosw/robot_model/urdf/gaz_models/cleaned_c/sensor_head_servo2.stl" scale="0.001 .001 .001"/>
      </geometry>
      <origin rpy="0 0 0" xyz="0 0 0"/>
      <material name="brown"/>
    </visual>
    <collision>
      <origin rpy="0 0 0" xyz="0 0 0"/>
      <geometry>
	 <!--use simplified model for collisions -->
         <mesh filename="/home/peter/rosw/robot_model/urdf/gaz_models/cleaned_c/sensor_head_servo2.stl" scale="0.001 .001 .001"/>
      </geometry>
    </collision>
    <inertial>
      <mass value="3"/>
      <inertia ixx="1.0" ixy="0.0" ixz="0.0" iyy="1.0" iyz="0.0" izz="1.0"/>
    </inertial>
  </link>

  <joint name="mount_plate_to_SH_Servo2_link" type="continuous">
    <axis xyz="0 1 0"/>
    <parent link="mounting_plate"/>
    <child link="SH_Servo2"/>
    <origin xyz="-0.078 -0.002 0.155"/>
    <limit effort="100" velocity="100"/>
    <dynamics damping="1" friction="0.2"/>
  </joint>







  <link name="laser_link" type="laser">
     <inertial>
       <mass value="0.001" />
       <origin xyz="0 0 0" />
       <inertia ixx="0.0001" ixy="0" ixz="0" iyy="0.000001" iyz="0" izz="0.0001" />
    </inertial>
  </link>


  <joint name="laser_joint" type="fixed">
     <axis xyz="0 1 0" rpy="0 0 1.4"/>
     <origin xyz="-0.25 0 0.40"/> 
     <parent link="base_link"/>
     <child link="laser_link"/>
  </joint>

 
  <link name="laser_box">
    <inertial>
      <mass value="0.1"/>
      <origin xyz="0 0 0.0"/>
      <inertia ixx="0.1" ixy="0" ixz="0" iyy="0.1" iyz="0" izz="0.1"/>
    </inertial>
    
    <visual>
      <origin rpy="0 0 0" xyz="0 0 0.0"/>
      <geometry>
        <cylinder radius=".03" length=".06"/>
      </geometry>

      <material name="Gazebo/Brown">
        <color rgba="0.5 0.2 0.2 5"/>
      </material>
    </visual>
    
    <collision>
      <origin rpy="0 0 0" xyz="0 0 0.0"/>
      <geometry>
        <cylinder radius=".03" length=".06"/>
      </geometry>
    </collision>
    
  </link>

<joint name="laser_box_to_laser_link" type="fixed">
    <parent link="laser_link"/>
    <child link="laser_box"/>
    <origin xyz="0 0 0"/>
  </joint>


  <gazebo reference="laser_link">
    <sensor:ray name="laser_link">
      <resRange>0.1</resRange>
      <rayCount>10</rayCount>
      <rangeCount>640</rangeCount>
      <laserCount>1</laserCount>
      <origin>0.0 0.0 0.0</origin>
      <displayRays>true</displayRays>
      
      <minAngle>-100</minAngle> -- scans own arms if -135~+135 
      <maxAngle>100</maxAngle>
      
      <minRange>0.07</minRange>
      <maxRange>10.0</maxRange>
      <updateRate>20.0</updateRate>
      <controller:gazebo_ros_laser name="laser_link_controller" plugin="libgazebo_ros_laser.so">
        <gaussianNoise>0.01</gaussianNoise>
        <alwaysOn>true</alwaysOn>
        <updateRate>20.0</updateRate>
        <topicName>laser_scan</topicName>
        <frameName>laser_link</frameName>
        <interface:laser name="gazebo_ros_base_laser_link_iface"/>
      </controller:gazebo_ros_laser>
    </sensor:ray>
    <material>Gazebo/Red</material>
  </gazebo>

</robot>
