<?xml version="1.0"?>
<robot name="tedusar_laser_alignment">
    
    <link name="la_base_link" >
        <visual>
            <geometry>
                <box size="0.03 0.04 0.08"/>
            </geometry>
            <material name="light_gray">
                <color rgba="0.4 0.4 0.4 1.0"/>
            </material>
            <origin rpy="0 0 0" xyz="0 0 0.04"/>
        </visual>
        <collision>
            <geometry>
                <box size="0.03 0.04 0.08"/>
            </geometry>
            <material name="light_gray">
                <color rgba="0.4 0.4 0.4 1.0"/>
            </material>
            <origin rpy="0 0 0" xyz="0 0 0.04"/>
        </collision>
	<inertial>
		<mass value="0.3"/> <!-- kg -->
		<inertia ixx="0.01" ixy="0.0" ixz="0.0" iyy="0.02" iyz="0.0" izz="0.01"/>
      		<origin rpy="0 0 0" xyz="0 0 0"/> <!--Center of mass -->
	</inertial>
    </link>
    
    <link name="la_servo1" >
        <visual>
            <geometry>
                <box size="0.035 0.035 0.05"/>
            </geometry>
            <material name="gray">
                <color rgba="0.2 0.2 0.2 1.0"/>
            </material>
            <origin rpy="0 0 0" xyz="-0.0175 0 -0.01"/>
        </visual>
        <collision>
            <geometry>
                <box size="0.035 0.035 0.05"/>
            </geometry>
            <material name="gray">
                <color rgba="0.2 0.2 0.2 1.0"/>
            </material>
            <origin rpy="0 0 0" xyz="-0.0175 0 -0.01"/>
        </collision>
    <inertial>
      <mass value="0.25"/> <!-- kg -->
      <inertia ixx="0.01" ixy="0.0" ixz="0.0" iyy="0.02" iyz="0.0" izz="0.01"/>
      <origin rpy="0 0 0" xyz="0 0 0"/> <!--Center of mass -->
    </inertial>
    </link>
    
    <link name="la_servo1_roll" />
    <link name="la_servo2" >
        <visual>
            <geometry>
                <box size="0.035 0.035 0.05"/>
            </geometry>
            <material name="gray"/>
            <origin rpy="0 0 0" xyz="0 0 -0.02"/>
        </visual>
        <collision>
            <geometry>
                <box size="0.035 0.035 0.05"/>
            </geometry>
            <material name="gray"/>
            <origin rpy="0 0 0" xyz="0 0 -0.02"/>
        </collision>
    <inertial>
      <mass value="0.25"/> <!-- kg -->
      <inertia ixx="0.01" ixy="0.0" ixz="0.0" iyy="0.02" iyz="0.0" izz="0.01"/>
      <origin rpy="0 0 0" xyz="0 0 0"/> <!--Center of mass -->
    </inertial>
    </link>
    
    <link name="la_servo2_pitch" >
        <visual>
            <geometry>
                <box size="0.043 0.015 0.045"/>
            </geometry>
            <material name="light_gray"/>
            <origin rpy="0 0 0" xyz="0 0 0.02"/>
        </visual>
        <collision>
            <geometry>
                <box size="0.043 0.015 0.045"/>
            </geometry>
            <material name="light_gray"/>
            <origin rpy="0 0 0" xyz="0 0 0.02"/>
        </collision>
    <inertial>
      <mass value="0.25"/> <!-- kg -->
      <inertia ixx="0.01" ixy="0.0" ixz="0.0" iyy="0.02" iyz="0.0" izz="0.01"/>
      <origin rpy="0 0 0" xyz="0 0 0"/> <!--Center of mass -->
    </inertial>
    </link>
    
    <link name="la_platform" >
        <visual>
            <geometry>
                <box size="0.050 0.050 0.005"/>
            </geometry>
            <material name="light_gray"/>
            <origin rpy="0 0 0" xyz="0 0 0.01"/>
        </visual>
        <collision>
            <geometry>
                <box size="0.050 0.050 0.005"/>
            </geometry>
            <material name="light_gray"/>
            <origin rpy="0 0 0" xyz="0 0 0.01"/>
        </collision>
    <inertial>
      <mass value="0.25"/> <!-- kg -->
      <inertia ixx="0.01" ixy="0.0" ixz="0.0" iyy="0.02" iyz="0.0" izz="0.01"/>
      <origin rpy="0 0 0" xyz="0 0 0"/> <!--Center of mass -->
    </inertial>
    </link>
    
    <link name="la_laser" >
        <visual>
            <geometry>
                <cylinder length="0.07" radius="0.03"/>
            </geometry>
            <material name="red">
                <color rgba="0.8 0.3 0.2 1.0"/>
            </material>
            <origin rpy="0 0 0" xyz="0 0 0.018"/>
        </visual>
        <collision>
            <geometry>
                <cylinder length="0.07" radius="0.03"/>
            </geometry>
            <material name="red">
                <color rgba="0.8 0.3 0.2 1.0"/>
            </material>
            <origin rpy="0 0 0" xyz="0 0 0.018"/>
        </collision>
    <inertial>
      <mass value="0.4"/> <!-- kg -->
      <inertia ixx="0.01" ixy="0.0" ixz="0.0" iyy="0.02" iyz="0.0" izz="0.01"/>
      <origin rpy="0 0 0" xyz="0 0 0"/> <!--Center of mass -->
    </inertial>
    </link>
    
    <joint name="la_base_to_servo1" type="fixed">
        <parent link="la_base_link"/>
        <child link="la_servo1"/>
        <origin xyz="0 0 0.07" rpy="0 0 0"/>
    </joint>
    
    <joint name="la_roll_joint" type="continuous">
        <parent link="la_servo1"/>
        <child link="la_servo1_roll"/>
        <origin xyz="0 0 0" rpy="0 0 0"/>
    </joint>
    
    <joint name="la_servo1_roll_to_servo2" type="fixed">
        <parent link="la_servo1_roll"/>
        <child link="la_servo2"/>
        <origin xyz="0.03 0 0.03" rpy="0 0 -1.570796"/>
    </joint>
    
    <joint name="la_pitch_joint" type="continuous">
        <parent link="la_servo2"/>
        <child link="la_servo2_pitch"/>
        <origin xyz="0 0 0" rpy="0 0 0"/>
    </joint>
    
    <joint name="la_servo2_pitch_to_platform" type="fixed">
        <parent link="la_servo2_pitch"/>
        <child link="la_platform"/>
        <origin xyz="0 0 0.02" rpy="0 0 1.570796"/>
    </joint>
    
    <joint name="la_platform_to_laser" type="fixed">
        <parent link="la_platform"/>
        <child link="la_laser"/>
        <origin xyz="0 0 0.03" rpy="0 0 0"/>
    </joint>
    
</robot>
